
<robot name ="mycar">
<!-- 
    添加一个尺寸极小的link ，再去关联初始的 link 与 base_link ,
    关节的高度刚好和base_link 下沉的高度一致(半个底盘的高度)
-->
    <link name ="base_footprint">
        <visual>           
            <geometry>
                <box size="0.001 0.001 0.001" />
            </geometry> 
        </visual>
    </link>

    <link name ="base_link">
        <visual>           
            <geometry>
                <box size="0.4 0.2 0.2" />
            </geometry> 
            <origin xyz="0 0 0" rpy="0 0 0" />           
            <material name="car_color">
                <color rgba = "0.2 0.3 1 0.3" />
            </material>
        </visual>
    </link>
    <!-- 2.摄像头link -->
    <link name ="camera">
        <visual>           
            <geometry>
                <box size="0.02 0.05 0.06" />
            </geometry> 
            <!-- 先使用默认(后期在进行修改) -->
            <origin xyz="0 0 0.03" rpy="0 0 0" />           
            <material name="camera">
                <color rgba = "0 0 1 0.5" />
            </material>
        </visual>
    </link>

    <!-- 关联 base_footprint 和link  -->
    <joint name="footprintbase" type="fixed" >
        <!-- 父级 link -->
        <parent link="base_footprint" />
        <!-- 子级 link -->
        <child link ="base_link" />
        <!-- 设置偏移量 -->
        <origin xyz="0 0 0.1" rpy="0 0 0" />
    </joint>

    <!-- 3.关节 -->
    <joint name="camerabase" type="continuous" >
        <!-- 父级 link -->
        <parent link="base_link" />
        <!-- 子级 link -->
        <child link ="camera" />
        <!-- 设置偏移量 -->
        <origin xyz="0.21 0 0.07" rpy="0 0 0" />
        <!-- 设置关节旋转参考的坐标轴 -->
        <axis xyz="0 0 1" />
    </joint>
        
</robot>